TESTS WITH ERRORS 
test14 (gradingtests.UnitTests)
Traceback (most recent call last):
  File "/Users/k2i/academics/automatedgradingapp/app/testing/kb-inference/gradingtests.py", line 405, in test14
    KB.kb_retract(fact2)
  File "/Users/k2i/academics/automatedgradingapp/app/testing/kb-inference/student_code.py", line 126, in kb_retract
    self.kb_retract_recursive(fact)
  File "/Users/k2i/academics/automatedgradingapp/app/testing/kb-inference/student_code.py", line 143, in kb_retract_recursive
    self.kb_retract_recursive(x)
  File "/Users/k2i/academics/automatedgradingapp/app/testing/kb-inference/student_code.py", line 153, in kb_retract_recursive
    self.facts.remove(fact_or_rule)
ValueError: list.remove(x): x not in list

-------------------------------
TESTS FAILED  
test5 (gradingtests.UnitTests)
Traceback (most recent call last):
  File "/Users/k2i/academics/automatedgradingapp/app/testing/kb-inference/gradingtests.py", line 151, in test5
    self.assertTrue(len(answer4) > 0)
AssertionError: False is not true

-------------------------------
TESTS SKIPPED 
-------------------------------
